Workbook

Sheet Summary
A1: ETC Lighting Controls Survey
A2: Levels B2-06
A3: Surveyed 2026-10-07 to 2026-10-09
A4: THIS SHEET IS NOT A SUBSTITUTE FOR THE SUBMITTAL DRAWINGS! PLEASE REFER TO SUBMITTALS BEFORE ACTING ON ANY NOTES IN THIS SHEET!
A6: Device status by floor
A7: Floor | B7: Surveyed | C7: Updated | D7: Installed, untested | E7: Issue | F7: Not installed | G7: No access | H7: Complete | I7: Total
A8: B2 | B8: 2026-10-09 | D8: =SUMPRODUCT((Devices!$A$4:$A$2000=$A8)*(Devices!$H$4:$H$2000=D$7)) -> 1 | E8: =SUMPRODUCT((Devices!$A$4:$A$2000=$A8)*(Devices!$H$4:$H$2000=E$7)) -> 3 | F8: =SUMPRODUCT((Devices!$A$4:$A$2000=$A8)*(Devices!$H$4:$H$2000=F$7)) -> 1 | G8: =SUMPRODUCT((Devices!$A$4:$A$2000=$A8)*(Devices!$H$4:$H$2000=G$7)) -> 0 | H8: =SUMPRODUCT((Devices!$A$4:$A$2000=$A8)*(Devices!$H$4:$H$2000=H$7)) -> 0 | I8: =SUM(D8:H8) -> 5
A9: B1 | B9: 2026-10-08 | D9: =SUMPRODUCT((Devices!$A$4:$A$2000=$A9)*(Devices!$H$4:$H$2000=D$7)) -> 6 | E9: =SUMPRODUCT((Devices!$A$4:$A$2000=$A9)*(Devices!$H$4:$H$2000=E$7)) -> 9 | F9: =SUMPRODUCT((Devices!$A$4:$A$2000=$A9)*(Devices!$H$4:$H$2000=F$7)) -> 12 | G9: =SUMPRODUCT((Devices!$A$4:$A$2000=$A9)*(Devices!$H$4:$H$2000=G$7)) -> 12 | H9: =SUMPRODUCT((Devices!$A$4:$A$2000=$A9)*(Devices!$H$4:$H$2000=H$7)) -> 0 | I9: =SUM(D9:H9) -> 39
A10: 01 | B10: 2026-10-07 | C10: 2026-10-08 | D10: =SUMPRODUCT((Devices!$A$4:$A$2000=$A10)*(Devices!$H$4:$H$2000=D$7)) -> 6 | E10: =SUMPRODUCT((Devices!$A$4:$A$2000=$A10)*(Devices!$H$4:$H$2000=E$7)) -> 7 | F10: =SUMPRODUCT((Devices!$A$4:$A$2000=$A10)*(Devices!$H$4:$H$2000=F$7)) -> 22 | G10: =SUMPRODUCT((Devices!$A$4:$A$2000=$A10)*(Devices!$H$4:$H$2000=G$7)) -> 1 | H10: =SUMPRODUCT((Devices!$A$4:$A$2000=$A10)*(Devices!$H$4:$H$2000=H$7)) -> 0 | I10: =SUM(D10:H10) -> 36
A11: 02 | B11: 2026-10-07 | C11: 2026-10-08 | D11: =SUMPRODUCT((Devices!$A$4:$A$2000=$A11)*(Devices!$H$4:$H$2000=D$7)) -> 26 | E11: =SUMPRODUCT((Devices!$A$4:$A$2000=$A11)*(Devices!$H$4:$H$2000=E$7)) -> 4 | F11: =SUMPRODUCT((Devices!$A$4:$A$2000=$A11)*(Devices!$H$4:$H$2000=F$7)) -> 15 | G11: =SUMPRODUCT((Devices!$A$4:$A$2000=$A11)*(Devices!$H$4:$H$2000=G$7)) -> 0 | H11: =SUMPRODUCT((Devices!$A$4:$A$2000=$A11)*(Devices!$H$4:$H$2000=H$7)) -> 0 | I11: =SUM(D11:H11) -> 45
A12: 03 | B12: 2026-10-07 | C12: 2026-10-08 | D12: =SUMPRODUCT((Devices!$A$4:$A$2000=$A12)*(Devices!$H$4:$H$2000=D$7)) -> 16 | E12: =SUMPRODUCT((Devices!$A$4:$A$2000=$A12)*(Devices!$H$4:$H$2000=E$7)) -> 9 | F12: =SUMPRODUCT((Devices!$A$4:$A$2000=$A12)*(Devices!$H$4:$H$2000=F$7)) -> 11 | G12: =SUMPRODUCT((Devices!$A$4:$A$2000=$A12)*(Devices!$H$4:$H$2000=G$7)) -> 0 | H12: =SUMPRODUCT((Devices!$A$4:$A$2000=$A12)*(Devices!$H$4:$H$2000=H$7)) -> 0 | I12: =SUM(D12:H12) -> 36
A13: 04 | B13: 2026-10-07 | C13: 2026-10-08 | D13: =SUMPRODUCT((Devices!$A$4:$A$2000=$A13)*(Devices!$H$4:$H$2000=D$7)) -> 2 | E13: =SUMPRODUCT((Devices!$A$4:$A$2000=$A13)*(Devices!$H$4:$H$2000=E$7)) -> 15 | F13: =SUMPRODUCT((Devices!$A$4:$A$2000=$A13)*(Devices!$H$4:$H$2000=F$7)) -> 14 | G13: =SUMPRODUCT((Devices!$A$4:$A$2000=$A13)*(Devices!$H$4:$H$2000=G$7)) -> 0 | H13: =SUMPRODUCT((Devices!$A$4:$A$2000=$A13)*(Devices!$H$4:$H$2000=H$7)) -> 0 | I13: =SUM(D13:H13) -> 31
A14: 06 | B14: 2026-10-07 | D14: =SUMPRODUCT((Devices!$A$4:$A$2000=$A14)*(Devices!$H$4:$H$2000=D$7)) -> 12 | E14: =SUMPRODUCT((Devices!$A$4:$A$2000=$A14)*(Devices!$H$4:$H$2000=E$7)) -> 0 | F14: =SUMPRODUCT((Devices!$A$4:$A$2000=$A14)*(Devices!$H$4:$H$2000=F$7)) -> 2 | G14: =SUMPRODUCT((Devices!$A$4:$A$2000=$A14)*(Devices!$H$4:$H$2000=G$7)) -> 0 | H14: =SUMPRODUCT((Devices!$A$4:$A$2000=$A14)*(Devices!$H$4:$H$2000=H$7)) -> 0 | I14: =SUM(D14:H14) -> 14
A15: 06M | B15: 2026-10-07 | D15: =SUMPRODUCT((Devices!$A$4:$A$2000=$A15)*(Devices!$H$4:$H$2000=D$7)) -> 1 | E15: =SUMPRODUCT((Devices!$A$4:$A$2000=$A15)*(Devices!$H$4:$H$2000=E$7)) -> 3 | F15: =SUMPRODUCT((Devices!$A$4:$A$2000=$A15)*(Devices!$H$4:$H$2000=F$7)) -> 0 | G15: =SUMPRODUCT((Devices!$A$4:$A$2000=$A15)*(Devices!$H$4:$H$2000=G$7)) -> 0 | H15: =SUMPRODUCT((Devices!$A$4:$A$2000=$A15)*(Devices!$H$4:$H$2000=H$7)) -> 0 | I15: =SUM(D15:H15) -> 4
A16: Total | D16: =SUM(D8:D15) -> 70 | E16: =SUM(E8:E15) -> 50 | F16: =SUM(F8:F15) -> 77 | G16: =SUM(G8:G15) -> 13 | H16: =SUM(H8:H15) -> 0 | I16: =SUM(I8:I15) -> 210
A18: Outstanding items by floor
A19: Floor | B19: Open | C19: In progress | D19: Closed | E19: Total
A20: B2 | B20: =SUMPRODUCT(('Punch List'!$A$4:$A$2000=$A20)*('Punch List'!$H$4:$H$2000=B$19)) -> 9 | C20: =SUMPRODUCT(('Punch List'!$A$4:$A$2000=$A20)*('Punch List'!$H$4:$H$2000=C$19)) -> 0 | D20: =SUMPRODUCT(('Punch List'!$A$4:$A$2000=$A20)*('Punch List'!$H$4:$H$2000=D$19)) -> 0 | E20: =SUM(B20:D20) -> 9
A21: B1 | B21: =SUMPRODUCT(('Punch List'!$A$4:$A$2000=$A21)*('Punch List'!$H$4:$H$2000=B$19)) -> 28 | C21: =SUMPRODUCT(('Punch List'!$A$4:$A$2000=$A21)*('Punch List'!$H$4:$H$2000=C$19)) -> 0 | D21: =SUMPRODUCT(('Punch List'!$A$4:$A$2000=$A21)*('Punch List'!$H$4:$H$2000=D$19)) -> 0 | E21: =SUM(B21:D21) -> 28
A22: 01 | B22: =SUMPRODUCT(('Punch List'!$A$4:$A$2000=$A22)*('Punch List'!$H$4:$H$2000=B$19)) -> 46 | C22: =SUMPRODUCT(('Punch List'!$A$4:$A$2000=$A22)*('Punch List'!$H$4:$H$2000=C$19)) -> 1 | D22: =SUMPRODUCT(('Punch List'!$A$4:$A$2000=$A22)*('Punch List'!$H$4:$H$2000=D$19)) -> 6 | E22: =SUM(B22:D22) -> 53
A23: 02 | B23: =SUMPRODUCT(('Punch List'!$A$4:$A$2000=$A23)*('Punch List'!$H$4:$H$2000=B$19)) -> 27 | C23: =SUMPRODUCT(('Punch List'!$A$4:$A$2000=$A23)*('Punch List'!$H$4:$H$2000=C$19)) -> 0 | D23: =SUMPRODUCT(('Punch List'!$A$4:$A$2000=$A23)*('Punch List'!$H$4:$H$2000=D$19)) -> 5 | E23: =SUM(B23:D23) -> 32
A24: 03 | B24: =SUMPRODUCT(('Punch List'!$A$4:$A$2000=$A24)*('Punch List'!$H$4:$H$2000=B$19)) -> 29 | C24: =SUMPRODUCT(('Punch List'!$A$4:$A$2000=$A24)*('Punch List'!$H$4:$H$2000=C$19)) -> 0 | D24: =SUMPRODUCT(('Punch List'!$A$4:$A$2000=$A24)*('Punch List'!$H$4:$H$2000=D$19)) -> 2 | E24: =SUM(B24:D24) -> 31
A25: 04 | B25: =SUMPRODUCT(('Punch List'!$A$4:$A$2000=$A25)*('Punch List'!$H$4:$H$2000=B$19)) -> 41 | C25: =SUMPRODUCT(('Punch List'!$A$4:$A$2000=$A25)*('Punch List'!$H$4:$H$2000=C$19)) -> 0 | D25: =SUMPRODUCT(('Punch List'!$A$4:$A$2000=$A25)*('Punch List'!$H$4:$H$2000=D$19)) -> 3 | E25: =SUM(B25:D25) -> 44
A26: 06 | B26: =SUMPRODUCT(('Punch List'!$A$4:$A$2000=$A26)*('Punch List'!$H$4:$H$2000=B$19)) -> 3 | C26: =SUMPRODUCT(('Punch List'!$A$4:$A$2000=$A26)*('Punch List'!$H$4:$H$2000=C$19)) -> 0 | D26: =SUMPRODUCT(('Punch List'!$A$4:$A$2000=$A26)*('Punch List'!$H$4:$H$2000=D$19)) -> 0 | E26: =SUM(B26:D26) -> 3
A27: 06M | B27: =SUMPRODUCT(('Punch List'!$A$4:$A$2000=$A27)*('Punch List'!$H$4:$H$2000=B$19)) -> 15 | C27: =SUMPRODUCT(('Punch List'!$A$4:$A$2000=$A27)*('Punch List'!$H$4:$H$2000=C$19)) -> 0 | D27: =SUMPRODUCT(('Punch List'!$A$4:$A$2000=$A27)*('Punch List'!$H$4:$H$2000=D$19)) -> 0 | E27: =SUM(B27:D27) -> 15
A28: Total | B28: =SUM(B20:B27) -> 198 | C28: =SUM(C20:C27) -> 1 | D28: =SUM(D20:D27) -> 16 | E28: =SUM(E20:E27) -> 215
A30: Outstanding items by owner
A31: Owner | B31: Open | C31: In progress | D31: Closed | E31: Total
A32: EC | B32: =SUMPRODUCT(('Punch List'!$G$4:$G$2000=$A32)*('Punch List'!$H$4:$H$2000=B$31)) -> 168 | C32: =SUMPRODUCT(('Punch List'!$G$4:$G$2000=$A32)*('Punch List'!$H$4:$H$2000=C$31)) -> 0 | D32: =SUMPRODUCT(('Punch List'!$G$4:$G$2000=$A32)*('Punch List'!$H$4:$H$2000=D$31)) -> 1 | E32: =SUM(B32:D32) -> 169
A33: ETC | B33: =SUMPRODUCT(('Punch List'!$G$4:$G$2000=$A33)*('Punch List'!$H$4:$H$2000=B$31)) -> 9 | C33: =SUMPRODUCT(('Punch List'!$G$4:$G$2000=$A33)*('Punch List'!$H$4:$H$2000=C$31)) -> 0 | D33: =SUMPRODUCT(('Punch List'!$G$4:$G$2000=$A33)*('Punch List'!$H$4:$H$2000=D$31)) -> 15 | E33: =SUM(B33:D33) -> 24
A34: EC/ETC | B34: =SUMPRODUCT(('Punch List'!$G$4:$G$2000=$A34)*('Punch List'!$H$4:$H$2000=B$31)) -> 21 | C34: =SUMPRODUCT(('Punch List'!$G$4:$G$2000=$A34)*('Punch List'!$H$4:$H$2000=C$31)) -> 1 | D34: =SUMPRODUCT(('Punch List'!$G$4:$G$2000=$A34)*('Punch List'!$H$4:$H$2000=D$31)) -> 0 | E34: =SUM(B34:D34) -> 22
A35: Total | B35: =SUM(B32:B34) -> 198 | C35: =SUM(C32:C34) -> 1 | D35: =SUM(D32:D34) -> 16 | E35: =SUM(E32:E34) -> 215
A42: Missing parts by floor
A43: Floor | B43: Needed | C43: Ordered | D43: On site | E43: Installed | F43: Total
A44: B2 | B44: =SUMPRODUCT(('Missing Parts'!$A$4:$A$2000=$A44)*('Missing Parts'!$I$4:$I$2000=B$43)) -> 3 | C44: =SUMPRODUCT(('Missing Parts'!$A$4:$A$2000=$A44)*('Missing Parts'!$I$4:$I$2000=C$43)) -> 0 | D44: =SUMPRODUCT(('Missing Parts'!$A$4:$A$2000=$A44)*('Missing Parts'!$I$4:$I$2000=D$43)) -> 0 | E44: =SUMPRODUCT(('Missing Parts'!$A$4:$A$2000=$A44)*('Missing Parts'!$I$4:$I$2000=E$43)) -> 0 | F44: =SUM(B44:E44) -> 3
A45: B1 | B45: =SUMPRODUCT(('Missing Parts'!$A$4:$A$2000=$A45)*('Missing Parts'!$I$4:$I$2000=B$43)) -> 8 | C45: =SUMPRODUCT(('Missing Parts'!$A$4:$A$2000=$A45)*('Missing Parts'!$I$4:$I$2000=C$43)) -> 0 | D45: =SUMPRODUCT(('Missing Parts'!$A$4:$A$2000=$A45)*('Missing Parts'!$I$4:$I$2000=D$43)) -> 0 | E45: =SUMPRODUCT(('Missing Parts'!$A$4:$A$2000=$A45)*('Missing Parts'!$I$4:$I$2000=E$43)) -> 0 | F45: =SUM(B45:E45) -> 8
A46: 01 | B46: =SUMPRODUCT(('Missing Parts'!$A$4:$A$2000=$A46)*('Missing Parts'!$I$4:$I$2000=B$43)) -> 17 | C46: =SUMPRODUCT(('Missing Parts'!$A$4:$A$2000=$A46)*('Missing Parts'!$I$4:$I$2000=C$43)) -> 0 | D46: =SUMPRODUCT(('Missing Parts'!$A$4:$A$2000=$A46)*('Missing Parts'!$I$4:$I$2000=D$43)) -> 1 | E46: =SUMPRODUCT(('Missing Parts'!$A$4:$A$2000=$A46)*('Missing Parts'!$I$4:$I$2000=E$43)) -> 2 | F46: =SUM(B46:E46) -> 20
A47: 02 | B47: =SUMPRODUCT(('Missing Parts'!$A$4:$A$2000=$A47)*('Missing Parts'!$I$4:$I$2000=B$43)) -> 10 | C47: =SUMPRODUCT(('Missing Parts'!$A$4:$A$2000=$A47)*('Missing Parts'!$I$4:$I$2000=C$43)) -> 0 | D47: =SUMPRODUCT(('Missing Parts'!$A$4:$A$2000=$A47)*('Missing Parts'!$I$4:$I$2000=D$43)) -> 0 | E47: =SUMPRODUCT(('Missing Parts'!$A$4:$A$2000=$A47)*('Missing Parts'!$I$4:$I$2000=E$43)) -> 0 | F47: =SUM(B47:E47) -> 10
A48: 03 | B48: =SUMPRODUCT(('Missing Parts'!$A$4:$A$2000=$A48)*('Missing Parts'!$I$4:$I$2000=B$43)) -> 16 | C48: =SUMPRODUCT(('Missing Parts'!$A$4:$A$2000=$A48)*('Missing Parts'!$I$4:$I$2000=C$43)) -> 0 | D48: =SUMPRODUCT(('Missing Parts'!$A$4:$A$2000=$A48)*('Missing Parts'!$I$4:$I$2000=D$43)) -> 0 | E48: =SUMPRODUCT(('Missing Parts'!$A$4:$A$2000=$A48)*('Missing Parts'!$I$4:$I$2000=E$43)) -> 0 | F48: =SUM(B48:E48) -> 16
A49: 04 | B49: =SUMPRODUCT(('Missing Parts'!$A$4:$A$2000=$A49)*('Missing Parts'!$I$4:$I$2000=B$43)) -> 12 | C49: =SUMPRODUCT(('Missing Parts'!$A$4:$A$2000=$A49)*('Missing Parts'!$I$4:$I$2000=C$43)) -> 0 | D49: =SUMPRODUCT(('Missing Parts'!$A$4:$A$2000=$A49)*('Missing Parts'!$I$4:$I$2000=D$43)) -> 1 | E49: =SUMPRODUCT(('Missing Parts'!$A$4:$A$2000=$A49)*('Missing Parts'!$I$4:$I$2000=E$43)) -> 0 | F49: =SUM(B49:E49) -> 13
...

Sheet Devices
A1: Devices
A2: Levels B2-06
A3: Level | B3: ID | C3: Category | D3: Device | E3: Type | F3: Room / Location | G3: Drawing Position | H3: Status | I3: Notes | J3: Photo | K3: Floor Order
A4: B2 | B4: B2-01 | C4: Relay panel | D4: CTB2LCPB | E4: Echo ERP-FT-241P (24x20 relays) | F4: Elec XXB2-2E02 | G4: Grid B-C / 9-8 | H4: Issue | I4: 0-10V not run. DMX run, not terminated. Network and 4x Unison wires land in ERP; need to be run down to the P-NSPS-D. | J4: 1 | K4: 1
A5: B2 | B5: B2-02 | C5: EBDK | D5: EBDK | E5: Emergency Bypass Detection Kit (CTB2LCPB) | F5: Elec XXB2-2E02 | G5: Grid C / 9-8 | H5: Installed, untested | K5: 1
A6: B2 | B6: B2-03 | C6: NSPS | D6: P-NSPS-D-KIT | E6: Paradigm network station power supply | F6: Elec XXB2-2E02 | G6: Grid B-C / 9-8 | H6: Issue | I6: Missing 48V jumper from power supply to NSPS. 120V not run to NSPS power supply. | J6: 2 | K6: 1
A7: B2 | B7: B2-S1 | C7: Station | D7: PI1002 | E7: Paradigm Inspire 2-button station | F7: Elevator Lobby B XXB2-C003, east | G7: Grid C / 9.5-9 | H7: Issue | I7: Missing cover. | J7: 3 | K7: 1
A8: B2 | B8: B2-D1 | C8: Sensor | D8: P-DOC-C-LR | E8: Paradigm ceiling occupancy sensor | F8: Elevator Lobby B XXB2-C003 | G8: Grid B-C / 9.5-9 | H8: Not installed | I8: Not Installed - box present. | J8: 4 | K8: 1
A9: B1 | B9: B1-01 | C9: Relay panel | D9: CTB1LCPB | E9: Echo ERP-FT-241P (24x20 relays) | F9: Elec WTB1-1E01; moved from Elec XXB1-2E02 | G9: WT Grid C.-D. / 4.-3 | H9: Issue | I9: Missing ERP-RTO jumper. Panel loads not landed. 0-10V not run. Both DMX run, not terminated. | J9: 1 | K9: 2
A10: B1 | B10: B1-02 | C10: EBDK | D10: EBDK | E10: Emergency Bypass Detection Kit (CTB1LCPB) | F10: Elec WTB1-1E01; moved from Elec XXB1-2E02 | G10: WT Grid C.-D. / 4.-3 | H10: Issue | I10: No sense feed. | J10: 1 | K10: 2
A11: B1 | B11: B1-S1 | C11: Station | D11: PI1002 | E11: Paradigm Inspire 2-button station | F11: Elevator Lobby B XXB1-C003, east | G11: Grid C / 9.5-9 | H11: Not installed | I11: Not Installed - no box. | K11: 2
A12: B1 | B12: B1-S2 | C12: Station | D12: PI1002 | E12: Paradigm Inspire 2-button station | F12: Corridor XXB1-C007 at Stair F XXB1-3S02 | G12: Grid A-B / 7 | H12: Not installed | I12: Not Installed - box present with wire. | J12: 4 | K12: 2
A13: B1 | B13: B1-S3 | C13: Station | D13: PI1002 | E13: Paradigm Inspire 2-button station | F13: Corridor XXB1-C005, north | G13: Grid E-F / 6.6-6.4 | H13: Issue | I13: Missing cover. | J13: 9, 10 | K13: 2
A14: B1 | B14: B1-S4 | C14: Station | D14: PI1002 | E14: Paradigm Inspire 2-button station | F14: Corridor XXB1-C005, south | G14: Grid E-F / 6.4-5.5 | H14: Issue | I14: Missing cover. | J14: 11 | K14: 2
A15: B1 | B15: B1-S5 | C15: Station | D15: PI1002 | E15: Paradigm Inspire 2-button station | F15: Elevator Lobby C XXB1-C002 | G15: Grid F / 6.4-5.5 | H15: Issue | I15: Missing cover. | K15: 2
A16: B1 | B16: B1-S6 | C16: Station | D16: PI1002 | E16: Paradigm Inspire 2-button station | F16: Corridor XXB1-C004 at IDF XXB1-1I05 | G16: Grid East of G / 6.6 | H16: Issue | I16: Missing cover. | K16: 2
A17: B1 | B17: B1-S7 | C17: Station | D17: PI1002 | E17: Paradigm Inspire 2-button station | F17: Corridor XXB1-C008, west | G17: Grid East of G / 6.6-6.4 | H17: Issue | I17: Missing cover. | K17: 2
A18: B1 | B18: B1-S8 | C18: Station | D18: PI1002 | E18: Paradigm Inspire 2-button station | F18: Corridor XXB1-C008, east at Gas Cyldr XXB1-1002 | G18: Grid East of G / 6.6 | H18: Issue | I18: Missing cover. | K18: 2
A19: B1 | B19: B1-S9 | C19: Station | D19: PI1002 | E19: Paradigm Inspire 2-button station | F19: Corridor at Drinking Fountain XXB1-1004 | G19: Grid East of G / 5.5 | H19: Issue | I19: Missing cover. | K19: 2
A20: B1 | B20: B1-S10 | C20: Station | D20: PI1002 | E20: Paradigm Inspire 2-button station | F20: Corridor WTB1-C016, north | G20: WT Grid C.-D. / 6.-5. | H20: No access | I20: Blocked by Walter Tower barricade. | K20: 2
A21: B1 | B21: B1-S11 | C21: Station | D21: PI1002 | E21: Paradigm Inspire 2-button station | F21: Corridor WTB1-C011, west | G21: WT Grid D.-E. / 6. | H21: No access | I21: Blocked by Walter Tower barricade. | K21: 2
A22: B1 | B22: B1-S12 | C22: Station | D22: PI1002 | E22: Paradigm Inspire 2-button station | F22: Corridor WTB1-C012 | G22: WT Grid E.-F. / 6.-5. | H22: No access | I22: Blocked by Walter Tower barricade. | K22: 2
A23: B1 | B23: B1-S13 | C23: Station | D23: PI1002 | E23: Paradigm Inspire 2-button station | F23: Fire Protection Closet WTB1-2008 | G23: WT Grid H.-J. / 6. | H23: No access | I23: Blocked by Walter Tower barricade. | K23: 2
A24: B1 | B24: B1-S14 | C24: Station | D24: PI1002 | E24: Paradigm Inspire 2-button station | F24: Corridor WTB1-C016 at Elec WTB1-1E01 | G24: WT Grid C.-D. / 3.-2. | H24: No access | I24: Blocked by Walter Tower barricade. | K24: 2
A25: B1 | B25: B1-S15 | C25: Station | D25: PI1002 | E25: Paradigm Inspire 2-button station | F25: Passage WTB1-C017 at Elec WTB1-1E01 | G25: WT Grid C.-D. / 3.-2. | H25: Installed, untested | K25: 2
A26: B1 | B26: B1-S16 | C26: Station | D26: PI1002 | E26: Paradigm Inspire 2-button station | F26: EVS Check-In Alcove WTB1-2044 | G26: WT Grid A.-B. / 4.-3. | H26: Installed, untested | K26: 2
A27: B1 | B27: B1-D1 | C27: Sensor | D27: P-DOC-W | E27: Paradigm wall occupancy sensor | F27: Corridor XXB1-C009 at Water Meter XXB1-3WM01 | G27: Grid B-C / 13-12.8 | H27: Not installed | I27: Not Installed - box present. | J27: 2 | K27: 2
A28: B1 | B28: B1-D2 | C28: Sensor | D28: P-DOC-W | E28: Paradigm wall occupancy sensor | F28: Corridor XXB1-C009 at Fan Room XXB1-2F01 | G28: Grid C-D / 13-12.8 | H28: Not installed | I28: Not Installed - box present. | J28: 3 | K28: 2
A29: B1 | B29: B1-D3 | C29: Sensor | D29: P-DOC-W | E29: Paradigm wall occupancy sensor | F29: Elevator Lobby B XXB1-C003, west | G29: Grid B / 9.5-9 | H29: Not installed | I29: Not Installed - no box. | K29: 2
A30: B1 | B30: B1-D4 | C30: Sensor | D30: P-DOC-C-LR | E30: Paradigm ceiling occupancy sensor | F30: Elevator Lobby B XXB1-C003 | G30: Grid B-C / 9.5-9 | H30: Not installed | I30: Not Installed - no box. | K30: 2
A31: B1 | B31: B1-D5 | C31: Sensor | D31: P-DOC-W | E31: Paradigm wall occupancy sensor | F31: Corridor XXB1-C007, north | G31: Grid A-B / 6.8 | H31: Not installed | I31: Not Installed - box present. | J31: 5 | K31: 2
A32: B1 | B32: B1-D6 | C32: Sensor | D32: P-DOC-W | E32: Paradigm wall occupancy sensor | F32: Corridor XXB1-C007, south at Confident Waste XXB1-3017 | G32: Grid A-B / 5.5 | H32: Not installed | I32: Not Installed - box present. | J32: 6 | K32: 2
A33: B1 | B33: B1-D7 | C33: Sensor | D33: P-DOC-W | E33: Paradigm wall occupancy sensor | F33: Corridor XXB1-C006 at Cart Wash XXB1-3007 | G33: Grid C-D / 5.5 | H33: Not installed | I33: Not Installed - box present. | J33: 7 | K33: 2
A34: B1 | B34: B1-D8 | C34: Sensor | D34: P-DOC-W | E34: Paradigm wall occupancy sensor | F34: Corridor XXB1-C006 at Trash Compactor XXB1-2TC01 | G34: Grid D-E / 5.5 | H34: Not installed | I34: Not Installed - box present. | J34: 8 | K34: 2
A35: B1 | B35: B1-D9 | C35: Sensor | D35: P-DOC-W | E35: Paradigm wall occupancy sensor | F35: Corridor XXB1-C005 at Elevator CT-C1 | G35: Grid E-F / 5.5 | H35: Installed, untested | K35: 2
A36: B1 | B36: B1-D10 | C36: Sensor | D36: P-DOC-C-LR | E36: Paradigm ceiling occupancy sensor | F36: Corridor XXB1-C005 | G36: Grid E-F / 6.6-6.4 | H36: Installed, untested | K36: 2
A37: B1 | B37: B1-D11 | C37: Sensor | D37: P-DOC-C-LR | E37: Paradigm ceiling occupancy sensor | F37: Elevator Lobby C XXB1-C002 | G37: Grid F / 6.4-5.5 | H37: Installed, untested | K37: 2
A38: B1 | B38: B1-D12 | C38: Sensor | D38: P-DOC-C-LR | E38: Paradigm ceiling occupancy sensor | F38: Corridor XXB1-C004 at IDF XXB1-1I05 | G38: Grid East of G / 6.6-6.4 | H38: Installed, untested | K38: 2
A39: B1 | B39: B1-D13 | C39: Sensor | D39: P-DOC-C-LR | E39: Paradigm ceiling occupancy sensor | F39: Corridor XXB1-C008, west | G39: Grid East of G / 6.6-6.4 | H39: Not installed | I39: Not Installed. | J39: 12 | K39: 2
A40: B1 | B40: B1-D14 | C40: Sensor | D40: P-DOC-C-LR | E40: Paradigm ceiling occupancy sensor | F40: Corridor XXB1-C008, east at Gas Cyldr XXB1-1002 | G40: Grid East of G / 6.6-6.4 | H40: Not installed | I40: Not Installed. | K40: 2
...

Sheet Connections
A1: Connections
A2: Levels B2-06
A3: Level | B3: ID | C3: From | D3: Cable | E3: To | F3: Qty | G3: Status | H3: Note | I3: Floor Order
A4: B2 | B4: C-01 | C4: CTB2LCPB | D4: X | E4: DMX to Level B1 CTB1LCPB | F4: 1 | G4: Issue | H4: Run, not terminated; no term kit. Survey drawing showed Level 01 | I4: 1
A5: B2 | B5: C-02 | C5: CTB2LCPB | D5: 0-10V | E5: Fixtures | F5: 1 | G5: Not installed | H5: Not run | I5: 1
A6: B2 | B6: C-03 | C6: CTB2LCPB | D6: P | E6: EBDK panic wire | F6: 1 | G6: Installed, untested | I6: 1
A7: B2 | B7: C-04 | C7: 120v Power | D7: 120V | E7: P-NSPS-D Power Supply | F7: 1 | G7: Not installed | H7: Not run | I7: 1
A8: B2 | B8: C-05 | C8: P-NSPS-D | D8: N | E8: Network to Level 01 | F8: 1 | G8: Issue | H8: Lands in ERP; needs to be run down to the NSPS below it | I8: 1
A9: B2 | B9: C-06 | C9: P-NSPS-D | D9: U | E9: Unison to Level B1 Devices | F9: 1 | G9: Issue | H9: Lands in ERP? (Not labeled); needs to be run down to the NSPS below it | I9: 1
A10: B2 | B10: C-07 | C10: Stations & Sensors | D10: U | E10: B2 Devices to P-NSPS-D | G10: Issue | H10: Lands in ERP; needs to be run down to the NSPS below it | I10: 1
A11: B2 | B11: C-08 | C11: P-NSPS-D | D11: U | E11: Unison from B2 station & sensor | G11: Issue | H11: Lands in ERP; needs to be run down to the NSPS below it | I11: 1
A12: B1 | B12: C-01 | C12: CTB1LCPB | D12: X | E12: DMX to Level 01 | F12: 1 | G12: Issue | H12: Run, not terminated; no term kit | I12: 2
A13: B1 | B13: C-02 | C13: CTB1LCPB | D13: X | E13: DMX to Level B2 | F13: 1 | G13: Issue | H13: Run, not terminated; no term kit | I13: 2
A14: B1 | B14: C-03 | C14: CTB1LCPB | D14: 0-10V | E14: Fixtures | F14: 1 | G14: Not installed | H14: Not run | I14: 2
A15: B1 | B15: C-04 | C15: CTB1LCPB | D15: P | E15: EBDK panic wire | F15: 1 | G15: Installed, untested | I15: 2
A16: B1 | B16: C-05 | C16: Stations & Sensors | D16: U | E16: Unison to Level B2 ERP | F16: 1 | G16: Issue | H16: Lands in B2 ERP; needs to be run down to the NSPS below it | I16: 2
A17: 01 | B17: C-01 | C17: CT01LCPB | D17: X | E17: DMX to Level 02 UFMP4 | F17: 1 | G17: Installed, untested | H17: Terminated, untested | I17: 3
A18: 01 | B18: C-02 | C18: CT01LCPB | D18: X | E18: DMX to Equipment rack | F18: 1 | G18: Installed, untested | H18: Terminated, untested | I18: 3
A19: 01 | B19: C-03 | C19: CT01LCPB | D19: 0-10V | E19: Fixtures | F19: 1 | G19: Issue | H19: Run, not terminated | I19: 3
A20: 01 | B20: C-04 | C20: CT01LCPB | D20: P | E20: EBDK panic wire | F20: 1 | G20: Installed, untested | I20: 3
A21: 01 | B21: C-05 | C21: CT01LCPA | D21: X | E21: DMX to Level 02 | F21: 1 | G21: Installed, untested | H21: Terminated, untested | I21: 3
A22: 01 | B22: C-06 | C22: CT01LCPA | D22: X | E22: DMX to Equipment rack | F22: 1 | G22: Installed, untested | H22: Terminated, untested | I22: 3
A23: 01 | B23: C-07 | C23: CT01LCPA | D23: 0-10V | E23: Fixtures | F23: 1 | G23: Issue | H23: Run, not terminated | I23: 3
A24: 01 | B24: C-08 | C24: CT01LCPA | D24: P | E24: EBDK panic wire | F24: 1 | G24: Installed, untested | I24: 3
A25: 01 | B25: C-09 | C25: Equipment rack | D25: X | E25: DMX to B3A Canyon | F25: 1 | G25: Not installed | H25: One DMX wire at equipment rack unidentified. Could be this?; no term kit | I25: 3
A26: 01 | B26: C-10 | C26: Equipment rack | D26: X | E26: DMX to C13A Oculus | F26: 1 | G26: Not installed | H26: One DMX wire at equipment rack unidentified. Could be this?; no term kit | I26: 3
A27: 01 | B27: C-11 | C27: Equipment rack | D27: X | E27: DMX to D1 ED Column Capital | F27: 1 | G27: Not installed | H27: One DMX wire at equipment rack unidentified. Could be this?; no term kit | I27: 3
A28: 01 | B28: C-12 | C28: Equipment rack | D28: X | E28: DMX to UFMP4 (7) | F28: 1 | G28: Not installed | H28: One DMX wire at equipment rack unidentified. Could be this?; no term kit | I28: 3
A29: 01 | B29: C-13 | C29: Equipment rack | D29: N | E29: Walter Tower ETC P-CCS | F29: 1 | G29: Not installed | H29: Not installed, Walter tower conduit empty | I29: 3
A30: 01 | B30: C-14 | C30: Equipment rack | D30: N | E30: Level 02 | F30: 1 | G30: Issue | H30: Net run, not terminated; destination might be wrong room | I30: 3
A31: 01 | B31: C-15 | C31: Equipment rack | D31: F | E31: Equipment rack Level 06 | F31: 1 | G31: Issue | H31: Fiber terminated; missing kit parts SGM1612, SGN1021 | I31: 3
A32: 01 | B32: C-16 | C32: Equipment rack | D32: NG | E32: P-TS7-E touchscreen | F32: 1 | G32: Not installed | H32: P-TS7-E not installed | I32: 3
A33: 01 | B33: C-17 | C33: Stations & Sensors | D33: U | E33: Devices to equipment rack | G33: Not installed | H33: No unison wire at equipment rack | I33: 3
A34: 01 | B34: C-18 | C34: Equipment rack | D34: X | E34: DMX to CT01LCPB | F34: 1 | G34: Issue | H34: Run, not terminated at rack; no term kit | I34: 3
A35: 01 | B35: C-19 | C35: Equipment rack | D35: X | E35: DMX to CT01LCPA | F35: 1 | G35: Issue | H35: Run, not terminated at rack; no term kit | I35: 3
A36: 01 | B36: C-20 | C36: Equipment rack | D36: X | E36: DMX to Level B1 CTB1LCPB | F36: 1 | G36: Issue | H36: Run, not terminated; no term kit (per Level B1). Likely the unidentified DMX wire at the rack? | I36: 3
A37: 01 | B37: C-21 | C37: Equipment rack | D37: N | E37: Network to Level B2 P-NSPS-D | F37: 1 | G37: Issue | H37: Run (per Level B2) | I37: 3
A38: 01 | B38: C-22 | C38: Equipment rack | D38: U | E38: Unison from stations & sensors | G38: Not installed | H38: No Unison wire at equipment rack | I38: 3
A39: 01 | B39: C-23 | C39: UFMP4 (7) | D39: X | E39: DMX to equipment rack | F39: 1 | G39: Not installed | H39: UFMP4s not installed; one DMX wire at the rack unidentified, could be this? | I39: 3
A40: 01 | B40: C-24 | C40: P-TS7-E | D40: NG | E40: Network & ground to equipment rack | F40: 1 | G40: Not installed | H40: P-TS7-E not installed | I40: 3
...

Sheet Punch List
A1: Outstanding items
A2: Levels B2-06
A3: Level | B3: # | C3: Device | D3: Item | E3: Type | F3: Photo | G3: Owner | H3: Tracking status | I3: Date closed | J3: Notes | K3: Floor Order
A4: B2 | B4: 1 | C4: CTB2LCPB | D4: Run and land 0-10V control wiring | E4: Cable not run | G4: EC | H4: Open | K4: 1
A5: B2 | B5: 2 | C5: CTB2LCPB | D5: Terminate DMX to Level B1 | E5: Missing part | G5: EC/ETC | H5: Open | J5: Waiting on DMX Termination Kits | K5: 1
A6: B2 | B6: 3 | C6: P-NSPS-D | D6: Land 48V jumper from power supply to NSPS | E6: Wiring | F6: 2 | G6: EC | H6: Open | J6: Provided in NSPS box | K6: 1
A7: B2 | B7: 4 | C7: P-NSPS-D | D7: Run 120V to NSPS power supply | E7: Cable not run | G7: EC | H7: Open | K7: 1
A8: B2 | B8: 5 | C8: P-NSPS-D | D8: Run network to P-NSPS-D | E8: Cable not run | F8: 1 | G8: EC | H8: Open | J8: Lands in ERP; needs to be run down to the NSPS below it | K8: 1
A9: B2 | B9: 6 | C9: P-NSPS-D | D9: Run Unison to P-NSPS-D (B2 & B1 stations and devices) | E9: Cable not run | F9: 1 | G9: EC | H9: Open | J9: 4x Unison land in ERP; need to be run down to the NSPS below it | K9: 1
A10: B2 | B10: 7 | C10: PI1002 S1 - Elevator Lobby B XXB2-C003 east | D10: Install cover | E10: Missing part | F10: 3 | G10: EC | H10: Open | J10: Confirm whether on site | K10: 1
A11: B2 | B11: 8 | C11: P-DOC-C-LR D1 - Elevator Lobby B XXB2-C003 | D11: Not installed: install sensor (box present) | E11: Not installed | F11: 4 | G11: EC | H11: Open | K11: 1
A12: B2 | B12: 9 | C12: All devices | D12: Missing all Device Neuron IDs | E12: Information | G12: EC | H12: Open | K12: 1
A13: B1 | B13: 1 | C13: CTB1LCPB | D13: Install ERP-RTO jumper | E13: Missing part | G13: EC | H13: Open | K13: 2
A14: B1 | B14: 2 | C14: CTB1LCPB | D14: Land panel loads | E14: Termination | G14: EC | H14: Open | K14: 2
A15: B1 | B15: 3 | C15: CTB1LCPB | D15: Run and land 0-10V control wiring | E15: Cable not run | G15: EC | H15: Open | K15: 2
A16: B1 | B16: 4 | C16: CTB1LCPB | D16: Terminate DMX to Level 01 | E16: Missing part | G16: EC/ETC | H16: Open | J16: Waiting on DMX Termination Kits | K16: 2
A17: B1 | B17: 5 | C17: CTB1LCPB | D17: Terminate DMX to Level B2 | E17: Missing part | G17: EC/ETC | H17: Open | J17: Waiting on DMX Termination Kits | K17: 2
A18: B1 | B18: 6 | C18: EBDK (CTB1LCPB) | D18: Provide sense feed to EBDK | E18: Cable not run | G18: EC | H18: Open | K18: 2
A19: B1 | B19: 7 | C19: Stations & sensors | D19: Unison runs land in the Level B2 ERP (CTB2LCPB) | E19: Information | G19: EC | H19: Open | J19: Need to be run down to the NSPS below it. Unison wire on B2 is unlabeled | K19: 2
A20: B1 | B20: 8 | C20: PI1002 S3 - Corridor XXB1-C005 north | D20: Install cover | E20: Missing part | F20: 10 | G20: EC | H20: Open | J20: Confirm whether on site | K20: 2
A21: B1 | B21: 9 | C21: PI1002 S4 - Corridor XXB1-C005 south | D21: Install cover | E21: Missing part | F21: 11 | G21: EC | H21: Open | J21: Confirm whether on site | K21: 2
A22: B1 | B22: 10 | C22: PI1002 S5 - Elevator Lobby C XXB1-C002 | D22: Install cover | E22: Missing part | G22: EC | H22: Open | J22: Confirm whether on site | K22: 2
A23: B1 | B23: 11 | C23: PI1002 S6 - Corridor XXB1-C004 at IDF XXB1-1I05 | D23: Install cover | E23: Missing part | G23: EC | H23: Open | J23: Confirm whether on site | K23: 2
A24: B1 | B24: 12 | C24: PI1002 S7 - Corridor XXB1-C008 west | D24: Install cover | E24: Missing part | G24: EC | H24: Open | J24: Confirm whether on site | K24: 2
A25: B1 | B25: 13 | C25: PI1002 S8 - Corridor XXB1-C008 east at Gas Cyldr XXB1-1002 | D25: Install cover | E25: Missing part | G25: EC | H25: Open | J25: Confirm whether on site | K25: 2
A26: B1 | B26: 14 | C26: PI1002 S9 - Corridor at Drinking Fountain XXB1-1004 | D26: Install cover | E26: Missing part | G26: EC | H26: Open | J26: Confirm whether on site | K26: 2
A27: B1 | B27: 15 | C27: PI1002 S1 - Elevator Lobby B XXB1-C003 east | D27: Not installed: install station | E27: Not installed | G27: EC | H27: Open | J27: No box | K27: 2
A28: B1 | B28: 16 | C28: PI1002 S2 - Corridor XXB1-C007 at Stair F XXB1-3S02 | D28: Not installed: install station (box present) | E28: Not installed | F28: 4 | G28: EC | H28: Open | K28: 2
A29: B1 | B29: 17 | C29: P-DOC-W D1 - Corridor XXB1-C009 at Water Meter XXB1-3WM01 | D29: Not installed: install sensor (box present) | E29: Not installed | F29: 2 | G29: EC | H29: Open | K29: 2
A30: B1 | B30: 18 | C30: P-DOC-W D2 - Corridor XXB1-C009 at Fan Room XXB1-2F01 | D30: Not installed: install sensor (box present) | E30: Not installed | F30: 3 | G30: EC | H30: Open | K30: 2
A31: B1 | B31: 19 | C31: P-DOC-W D3 - Elevator Lobby B XXB1-C003 west | D31: Not installed: install sensor | E31: Not installed | G31: EC | H31: Open | J31: No box | K31: 2
A32: B1 | B32: 20 | C32: P-DOC-C-LR D4 - Elevator Lobby B XXB1-C003 | D32: Not installed: install sensor | E32: Not installed | G32: EC | H32: Open | J32: No box | K32: 2
A33: B1 | B33: 21 | C33: P-DOC-W D5 - Corridor XXB1-C007 north | D33: Not installed: install sensor (box present) | E33: Not installed | F33: 5 | G33: EC | H33: Open | K33: 2
A34: B1 | B34: 22 | C34: P-DOC-W D6 - Corridor XXB1-C007 south at Confident Waste XXB1-3017 | D34: Not installed: install sensor (box present) | E34: Not installed | F34: 6 | G34: EC | H34: Open | K34: 2
A35: B1 | B35: 23 | C35: P-DOC-W D7 - Corridor XXB1-C006 at Cart Wash XXB1-3007 | D35: Not installed: install sensor (box present) | E35: Not installed | F35: 7 | G35: EC | H35: Open | K35: 2
A36: B1 | B36: 24 | C36: P-DOC-W D8 - Corridor XXB1-C006 at Trash Compactor XXB1-2TC01 | D36: Not installed: install sensor (box present) | E36: Not installed | F36: 8 | G36: EC | H36: Open | K36: 2
A37: B1 | B37: 25 | C37: P-DOC-C-LR D13 - Corridor XXB1-C008 west | D37: Not installed: install sensor | E37: Not installed | F37: 12 | G37: EC | H37: Open | K37: 2
A38: B1 | B38: 26 | C38: P-DOC-C-LR D14 - Corridor XXB1-C008 east at Gas Cyldr XXB1-1002 | D38: Not installed: install sensor | E38: Not installed | G38: EC | H38: Open | K38: 2
A39: B1 | B39: 27 | C39: Walter Tower east wing | D39: Gain access; survey 5x PI1002 (S10-S14) and 7x P-DOC-C-LR (D15-D21) in Corridors WTB1-C010, C011, C012, C016 and Fire Protection Closet WTB1-2008 | E39: Access | G39: ETC | H39: Open | J39: Blocked by Walter Tower barricade | K39: 2
A40: B1 | B40: 28 | C40: All devices | D40: Missing all Device Neuron IDs | E40: Information | G40: EC | H40: Open | K40: 2
...

Sheet Missing Parts
A1: Missing Parts
A2: Levels B2-06
A3: Level | B3: # | C3: Device / Location | D3: Part | E3: Part no. | F3: Qty | G3: Owner | H3: Source | I3: Part status | J3: Notes | K3: Floor Order
A4: B2 | B4: 1 | C4: CTB2LCPB | D4: DMX termination kit - Level B1 run | F4: 1 | G4: EC | H4: Punch #2 | I4: Needed | J4: Need to be ordered | K4: 1
A5: B2 | B5: 2 | C5: S1 | D5: PI1002 cover | F5: 1 | G5: EC | H5: Punch #7 | I5: Needed | J5: Confirm whether on site (provided in box) | K5: 1
A6: B2 | B6: 3 | C6: D1 | D6: P-DOC-C-LR sensor | E6: P-DOC-C-LR | F6: 1 | G6: EC | H6: Punch #8 | I6: Needed | J6: Confirm whether on site | K6: 1
A7: B1 | B7: 1 | C7: CTB1LCPB | D7: ERP-RTO jumper | F7: 1 | G7: EC | H7: Punch #1 | I7: Needed | J7: Need to be ordered | K7: 2
A8: B1 | B8: 2 | C8: CTB1LCPB | D8: DMX termination kit - Level 01 run | F8: 1 | G8: EC | H8: Punch #4 | I8: Needed | J8: Need to be ordered | K8: 2
A9: B1 | B9: 3 | C9: CTB1LCPB | D9: DMX termination kit - Level B2 run | F9: 1 | G9: EC | H9: Punch #5 | I9: Needed | J9: Need to be ordered | K9: 2
A10: B1 | B10: 4 | C10: S3-S9 | D10: PI1002 cover | F10: 7 | G10: EC | H10: Punch #8-14 | I10: Needed | J10: Confirm whether on site (provided in box) | K10: 2
A11: B1 | B11: 5 | C11: S1, D3, D4 | D11: Backbox for device | F11: 3 | G11: EC | H11: Punch #15, #19, #20 | I11: Needed | J11: Confirm whether on site | K11: 2
A12: B1 | B12: 6 | C12: S1, S2 | D12: PI1002 station | E12: PI1002 | F12: 2 | G12: EC | H12: Punch #15, #16 | I12: Needed | J12: Confirm whether on site | K12: 2
A13: B1 | B13: 7 | C13: D1-D3, D5-D8 | D13: P-DOC-W sensor | E13: P-DOC-W | F13: 7 | G13: EC | H13: Punch #17-19, #21-24 | I13: Needed | J13: Confirm whether on site | K13: 2
A14: B1 | B14: 8 | C14: D4, D13, D14 | D14: P-DOC-C-LR sensor | E14: P-DOC-C-LR | F14: 3 | G14: EC | H14: Punch #20, #25, #26 | I14: Needed | J14: Confirm whether on site | K14: 2
A15: 01 | B15: 1 | C15: CT01LCPB | D15: ERP-RTO jumper | F15: 1 | G15: EC | H15: Punch #1 | I15: Needed | J15: Need to be ordered | K15: 3
A16: 01 | B16: 2 | C16: CT01LCPB, CT01LCPA | D16: ERP-FT-LVD (0-10V card) | E16: ERP-FT-LVD | F16: 2 | G16: EC | H16: Punch #38, #39 | I16: Needed | J16: Need to be ordered | K16: 3
A17: 01 | B17: 3 | C17: Equipment rack | D17: 1U brush panel | F17: 1 | G17: EC | H17: Punch #7 | I17: Needed | J17: Confirm whether on site | K17: 3
A18: 01 | B18: 4 | C18: Equipment rack | D18: Fiber kit part | E18: N2019 | F18: 1 | G18: EC | H18: Punch #8 | I18: Installed | J18: Verified 10/8 | K18: 3
A19: 01 | B19: 5 | C19: Equipment rack | D19: Fiber kit part | E19: SGN1253 | F19: 1 | G19: EC | H19: Punch #8 | I19: Installed | J19: Verified 10/8 | K19: 3
A20: 01 | B20: 6 | C20: Equipment rack | D20: Fiber kit part | E20: SGM1612 | F20: 1 | G20: EC | H20: Punch #8 | I20: Needed | J20: Need to be ordered | K20: 3
A21: 01 | B21: 7 | C21: Equipment rack | D21: Fiber kit part | E21: SGN1021 | F21: 1 | G21: EC | H21: Punch #8 | I21: Needed | J21: Need to be ordered | K21: 3
A22: 01 | B22: 8 | C22: Equipment rack | D22: DMX termination kit - B3A Canyon run | F22: 1 | G22: EC | H22: Punch #42 | I22: Needed | J22: Need to be ordered | K22: 3
A23: 01 | B23: 9 | C23: Equipment rack | D23: DMX termination kit - C13A Oculus run | F23: 1 | G23: EC | H23: Punch #43 | I23: Needed | J23: Need to be ordered | K23: 3
A24: 01 | B24: 10 | C24: Equipment rack | D24: DMX termination kit - D1 ED Column Capital run | F24: 1 | G24: EC | H24: Punch #44 | I24: Needed | J24: Need to be ordered | K24: 3
A25: 01 | B25: 11 | C25: Equipment rack | D25: DMX termination kit - UFMP4 run | F25: 1 | G25: EC | H25: Punch #45 | I25: Needed | J25: Need to be ordered | K25: 3
A26: 01 | B26: 12 | C26: Info Desk WT01-1046 | D26: P-TS7-E 7in touchscreen | E26: P-TS7-E | F26: 1 | G26: EC | H26: Punch #10 | I26: Needed | J26: Confirm whether on site | K26: 3
A27: 01 | B27: 13 | C27: Vest WT01-1044, BH OBS 47, 48 | D27: Foundry UFMP4 | E27: UFMP4 | F27: 3 | G27: EC | H27: Punch #11-13 | I27: Needed | J27: Confirm whether on site | K27: 3
A28: 01 | B28: 14 | C28: BH OBS 49, 50, 51, 52 | D28: Foundry UFMP4 | E28: UFMP4 | F28: 4 | G28: EC | H28: Punch #14-17 | I28: On site | J28: On site above ceiling; needs to be installed | K28: 3
A29: 01 | B29: 15 | C29: S5 | D29: Backbox for station | F29: 1 | G29: EC | H29: Punch #22 | I29: Needed | J29: Confirm whether on site | K29: 3
A30: 01 | B30: 16 | C30: S5, S7-S14, S20, S22 | D30: PI1104 station | E30: PI1104 | F30: 11 | G30: EC | H30: Punch #22-28, #30, #31, #33, #52 | I30: Needed | J30: Confirm whether on site | K30: 3
A31: 01 | B31: 17 | C31: S16, S18 | D31: PI1004 station | E31: PI1004 | F31: 2 | G31: EC | H31: Punch #32, #51 | I31: Needed | J31: Confirm whether on site | K31: 3
A32: 01 | B32: 18 | C32: D1 | D32: P-DOC-C-LR sensor | E32: P-DOC-C-LR | F32: 1 | G32: EC | H32: Punch #34 | I32: Needed | J32: Confirm whether on site | K32: 3
A33: 01 | B33: 19 | C33: Equipment rack | D33: DMX termination kit - CT01LCPB run | F33: 1 | G33: EC | H33: Punch #40 | I33: Needed | J33: Need to be ordered | K33: 3
A34: 01 | B34: 20 | C34: Equipment rack | D34: DMX termination kit - CT01LCPA run | F34: 1 | G34: EC | H34: Punch #41 | I34: Needed | J34: Need to be ordered | K34: 3
A35: 02 | B35: 1 | C35: CT02LCPA | D35: DMX termination kit - Level 03 run | F35: 1 | G35: EC | H35: Punch #4 | I35: Needed | J35: Need to be ordered | K35: 4
A36: 02 | B36: 2 | C36: CT02LCPA | D36: DMX termination kit - Level 01 run | F36: 1 | G36: EC | H36: Punch #5 | I36: Needed | J36: Need to be ordered | K36: 4
A37: 02 | B37: 3 | C37: CT02LCPB | D37: DMX termination kit - Level 03 run | F37: 1 | G37: EC | H37: Punch #9 | I37: Needed | J37: Need to be ordered | K37: 4
A38: 02 | B38: 4 | C38: CT02LCPB | D38: DMX termination kit - UFMP4 run | F38: 1 | G38: EC | H38: Punch #10 | I38: Needed | J38: Need to be ordered | K38: 4
A39: 02 | B39: 5 | C39: Elec XX02-1E01 | D39: P-NSPS-D-KIT | E39: P-NSPS-D-KIT | F39: 1 | G39: EC | H39: Punch #7 | I39: Needed | J39: Confirm whether on site | K39: 4
A40: 02 | B40: 6 | C40: Elec XX02-1E02 | D40: Foundry UFMP4 | E40: UFMP4 | F40: 1 | G40: EC | H40: Punch #12 | I40: Needed | J40: Confirm whether on site | K40: 4
...

Sheet Photo Log
A1: Photo Log
A2: Levels B2-06
A3: Level | B3: Photo | C3: Location | D3: Subject | E3: What it shows | F3: Device ID | G3: Floor Order | H3: Image
A4: B2 | B4: 1 | C4: Elec XXB2-2E02 | D4: CTB2LCPB - wires in ERP | E4: Relay panel open; network and Unison wires land in ERP. | F4: B2-01 | G4: 1
A5: B2 | B5: 2 | C5: Elec XXB2-2E02 | D5: P-NSPS-D - 48V jumper | E5: NSPS in enclosure; 48V jumper from power supply not landed. | F5: B2-03 | G5: 1
A6: B2 | B6: 3 | C6: Elevator Lobby B XXB2-C003 | D6: PI1002 S1 - missing cover | E6: Station on conduit box; no cover. | F6: B2-S1 | G6: 1
A7: B2 | B7: 4 | C7: Elevator Lobby B XXB2-C003 | D7: P-DOC-C-LR D1 - NI | E7: Conduit box open at ceiling; no device. | F7: B2-D1 | G7: 1
A8: B1 | B8: 1 | C8: Elec WTB1-1E01 | D8: CTB1LCPB / EBDK - moved | E8: Relay panel and EBDK in new location. | F8: B1-01, B1-02 | G8: 2
A9: B1 | B9: 2 | C9: Corridor XXB1-C009 | D9: P-DOC-W D1 - NI | E9: Box on conduit; no sensor. | F9: B1-D1 | G9: 2
A10: B1 | B10: 3 | C10: Corridor XXB1-C009 at Fan Room XXB1-2F01 | D10: P-DOC-W D2 - NI | E10: Box on conduit; no sensor. | F10: B1-D2 | G10: 2
A11: B1 | B11: 4 | C11: Corridor XXB1-C007 at Stair F XXB1-3S02 | D11: PI1002 S2 - NI | E11: Box present with wire; no station. | F11: B1-S2 | G11: 2
A12: B1 | B12: 5 | C12: Corridor XXB1-C007 | D12: P-DOC-W D5 - NI | E12: Empty box on wall. | F12: B1-D5 | G12: 2
A13: B1 | B13: 6 | C13: Corridor XXB1-C007 at Confident Waste XXB1-3017 | D13: P-DOC-W D6 - NI | E13: Empty box on wall. | F13: B1-D6 | G13: 2
A14: B1 | B14: 7 | C14: Corridor XXB1-C006 at Cart Wash XXB1-3007 | D14: P-DOC-W D7 - NI | E14: Empty box on wall. | F14: B1-D7 | G14: 2
A15: B1 | B15: 8 | C15: Corridor XXB1-C006 at Trash Compactor XXB1-2TC01 | D15: P-DOC-W D8 - NI | E15: Empty box on wall. | F15: B1-D8 | G15: 2
... A79: 06M | B79: 3 | C79: Below CT06LCPB | D79: EBDK | E79: Emergency Bypass Detection Kit, keyed, complete. | F79: 06M-03 | G79: 8

Sheet Lists
A1: Device status | B1: Tracking status | C1: Part status | D1: Connection status
A2: Complete | B2: Open | C2: Needed | D2: Complete
A3: Installed, untested | B3: In progress | C3: Ordered | D3: Installed, untested
A4: Issue | B4: Closed | C4: On site | D4: Issue
A5: Not installed | C5: Installed | D5: Not installed
A6: No access | D6: No access
D7: Not started
